Workbook

Sheet Raw Data
A1: Transaction ID | B1: Date | C1: Customer ID | D1: Customer Name | E1: Product ID | F1: Product | G1: Category | H1: Quantity | I1: Unit Price (₦) | J1: Region | K1: Salesperson | L1: Payment Method | M1: Payment Status
A2: TXN001 | B2: 46235 | C2: C008 | D2: Joseph Adebayo | E2: P004 | F2: Sliced Bread | G2: Bakery | H2: 2 | I2: 2200 | J2: Lagos | K2: Chinedu | L2: Card | M2: Paid
A3: TXN002 | B3: 46236 | C3: C005 | D3: Esther Johnson | E3: P007 | F3: Bottled Water | G3: Beverages | H3: 3 | I3: 500 | J3: Lagos | K3: Kemi | L3: Transfer | M3: Paid
A4: TXN003 | B4: 46237 | C4: C002 | D4: Daniel Okafor | E4: P002 | F4: Spaghetti | G4: Groceries | H4: 4 | I4: 1800 | J4: Ibadan | K4: Tolu | L4: POS | M4: Paid
A5: TXN004 | B5: 46238 | C5: C009 | D5: Deborah Obi | E5: P005 | F5: Meat Pie | G5: Bakery | H5: 5 | I5: 1800 | J5: Enugu | K5: Amaka | L5: Cash | M5: Paid
A6: TXN005 | B6: 46239 | C6: C006 | D6: David Yusuf | E6: P008 | F6: Liquid Soap | G6: Household | H6: 6 | I6: 3500 | J6: Abuja | K6: Chinedu | L6: Card | M6: Pending
A7: TXN006 | B7: 46240 | C7: C003 | D7: Grace Adeyemi | E7: P003 | F7: Peak Milk | G7: Groceries | H7: 7 | I7: 3200 | J7: Abuja | K7: Kemi | L7: Transfer | M7: Paid
A8: TXN007 | B8: 46241 | C8: C010 | D8: Peter James | E8: P006 | F8: Malt Drink | G8: Beverages | H8: 8 | I8: 1200 | J8: Abuja | K8: Tolu | L8: POS | M8: Paid
A9: TXN008 | B9: 46242 | C9: C007 | D9: Miriam Balogun | E9: P001 | F9: Premium Rice 5kg | G9: Groceries | H9: 1 | I9: 14500 | J9: Ibadan | K9: Amaka | L9: Cash | M9: Paid
A10: TXN009 | B10: 46243 | C10: C004 | D10: Samuel Eze | E10: P004 | F10: Sliced Bread | G10: Bakery | H10: 2 | I10: 2200 | J10: Enugu | K10: Chinedu | L10: Card | M10: Paid
A11: TXN010 | B11: 46244 | C11: C001 | D11: Aisha Bello | E11: P007 | F11: Bottled Water | G11: Beverages | H11: 3 | I11: 500 | J11: Lagos | K11: Kemi | L11: Transfer | M11: Pending
A12: TXN011 | B12: 46245 | C12: C008 | D12: Joseph Adebayo | E12: P002 | F12: Spaghetti | G12: Groceries | H12: 4 | I12: 1800 | J12: Lagos | K12: Tolu | L12: POS | M12: Paid
A13: TXN012 | B13: 46246 | C13: C005 | D13: aisha bello | E13: P005 | F13: Meat Pie | G13: Bakery | H13: 5 | I13: 1800 | J13: Lagos | K13: Amaka | L13: Cash | M13: Paid
... A58: TXN057 | B58: 46235 | C58: C010 | D58: Peter James | E58: P004 | F58: Sliced Bread | G58: Bakery | H58: 2 | I58: 2200 | J58: Abuja | K58: Chinedu | L58: Card | M58: Paid
A59: TXN058 | B59: 46236 | C59: C007 | E59: P007 | F59: Bottled Water | G59: Beverages | H59: 3 | I59: 500 | J59: Ibadan | K59: Kemi | L59: Transfer | M59: Paid
A60: TXN059 | B60: 46237 | C60: C004 | D60: Samuel Eze | E60: P002 | F60: Spaghetti | G60: Groceries | H60: 4 | I60: 1800 | J60: Enugu | K60: Tolu | L60: POS | M60: Paid
A61: TXN060 | B61: 46238 | C61: C001 | D61: Aisha Bello | E61: P005 | F61: Meat Pie | G61: Bakery | H61: 5 | I61: 1800 | J61: Lagos | K61: Amaka | L61: Cash | M61: Pending
A62: TXN061 | B62: 46239 | C62: C008 | D62: Joseph Adebayo | E62: P008 | F62: Liquid Soap | G62: Household | H62: 6 | I62: 3500 | J62: Lagos | K62: Chinedu | L62: Card | M62: Paid
A63: TXN062 | B63: 46240 | C63: C005 | D63: Esther Johnson | E63: P003 | F63: Peak Milk | G63: Groceries | H63: 7 | I63: 3200 | J63: Lagos | K63: Kemi | L63: Transfer | M63: Paid
A64: TXN063 | B64: 46241 | C64: C002 | D64: Daniel Okafor | E64: P006 | F64: Malt Drink | G64: Beverages | H64: 8 | I64: 1200 | J64: Ibadan | K64: Tolu | L64: POS | M64: Paid
A65: TXN064 | B65: 46242 | C65: C009 | D65: Deborah Obi | E65: P001 | F65: Premium Rice 5kg | G65: Groceries | H65: 1 | I65: 14500 | J65: Enugu | K65: Amaka | L65: Cash | M65: Paid
A66: TXN065 | B66: 46243 | C66: C006 | D66: David Yusuf | E66: P004 | F66: Sliced Bread | G66: Bakery | H66: 2 | I66: 2200 | J66: Abuja | K66: Chinedu | L66: Card | M66: Pending
A67: TXN066 | B67: 46244 | C67: C003 | D67: Grace Adeyemi | E67: P007 | F67: Bottled Water | G67: Beverages | H67: 3 | I67: 500 | J67: Abuja | K67: Kemi | L67: Transfer | M67: Paid
A68: TXN067 | B68: 46245 | C68: C010 | D68: Peter James | E68: P002 | F68: Spaghetti | G68: Groceries | H68: 4 | I68: 1800 | J68: Abuja | K68: Tolu | L68: POS | M68: Paid
A69: TXN068 | B69: 46246 | C69: C007 | D69: Miriam Balogun | E69: P005 | F69: Meat Pie | G69: Bakery | H69: 5 | I69: 1800 | J69: Ibadan | K69: Amaka | L69: Cash | M69: Paid
A70: TXN069 | B70: 46247 | C70: C004 | D70: Samuel Eze | E70: P008 | F70: Liquid Soap | G70: Household | H70: 6 | I70: 3500 | J70: Enugu | K70: Chinedu | L70: Card | M70: Paid
A71: TXN070 | B71: 46248 | C71: C001 | D71: Aisha Bello | E71: P003 | F71: Peak Milk | G71: Groceries | H71: 7 | I71: 3200 | J71: Lagos | K71: Kemi | L71: Transfer | M71: Pending
... A73: TXN072 | B73: 46250 | C73: C005 | D73: Esther Johnson | E73: P001 | F73: Premium Rice 5kg | G73: Groceries | H73: 1 | I73: 14500 | J73: Lagos | K73: Amaka | L73: Cash | M73: Paid
A74: TXN073 | B74: 46251 | C74: C002 | D74: Daniel Okafor | E74: P004 | F74: Sliced Bread | G74: Bakery | H74: 2 | I74: 2200 | K74: Chinedu | L74: Card | M74: Paid
A75: TXN074 | B75: 46252 | C75: C009 | D75: Deborah Obi | E75: P007 | F75: Bottled Water | G75: Beverages | H75: 3 | I75: 500 | J75: Enugu | K75: Kemi | L75: Transfer | M75: Paid
A76: TXN075 | B76: 46253 | C76: C006 | D76: David Yusuf | E76: P002 | F76: Spaghetti | G76: Groceries | H76: 4 | I76: 1800 | J76: Abuja | K76: Tolu | L76: POS | M76: Pending
A77: TXN076 | B77: 46254 | C77: C003 | D77: Grace Adeyemi | E77: P005 | F77: Meat Pie | G77: Bakery | H77: 5 | I77: 1800 | J77: Abuja | K77: Amaka | L77: Cash | M77: Paid
A78: TXN077 | B78: 46255 | C78: C010 | D78: Peter James | E78: P008 | F78: Liquid Soap | G78: Household | H78: 6 | I78: 3500 | J78: Abuja | K78: Chinedu | L78: Card | M78: Paid
A79: TXN078 | B79: 46256 | C79: C007 | D79: Miriam Balogun | E79: P003 | F79: Peak Milk | G79: Groceries | H79: 7 | I79: 3200 | J79: Ibadan | K79: Kemi | L79: Transfer | M79: Paid
A80: TXN079 | B80: 46257 | C80: C004 | D80: Samuel Eze | E80: P006 | F80: Malt Drink | G80: Beverages | H80: 8 | I80: 1200 | J80: Enugu | K80: Tolu | L80: POS | M80: Paid
A81: TXN080 | B81: 46258 | C81: C001 | D81: Aisha Bello | E81: P001 | F81: Premium Rice 5kg | G81: Groceries | H81: 1 | I81: 14500 | J81: Lagos | K81: Amaka | L81: Cash | M81: Pending
A82: TXN081 | B82: 46259 | C82: C008 | D82: Joseph Adebayo | E82: P004 | F82: Sliced Bread | G82: Bakery | H82: 2 | I82: 2200 | J82: Lagos | K82: Chinedu | L82: Card | M82: Paid
A83: TXN082 | B83: 46260 | C83: C005 | D83: Esther Johnson | E83: P007 | F83: Bottled Water | G83: Beverages | H83: 3 | I83: 500 | J83: Lagos | K83: Kemi | L83: Transfer | M83: Paid
A84: TXN083 | B84: 46261 | C84: C002 | D84: Daniel Okafor | E84: P002 | F84: Spaghetti | G84: Groceries | H84: 4 | I84: 1800 | J84: Ibadan | K84: Tolu | L84: POS | M84: Paid
A85: TXN084 | B85: 46262 | C85: C009 | D85: Deborah Obi | E85: P005 | F85: Meat Pie | G85: Bakery | H85: 5 | I85: 1800 | J85: Enugu | K85: Amaka | L85: Cash | M85: Paid
...

Sheet Clean sheet
A1: =PROPER(TRIM('Raw Data'!A1)) -> Transaction Id | B1: Date | C1: =TRIM('Raw Data'!C1) -> Customer ID | D1: =TRIM('Raw Data'!D1) -> Customer Name | E1: =TRIM('Raw Data'!E1) -> Product ID | F1: =TRIM('Raw Data'!F1) -> Product | G1: =TRIM('Raw Data'!G1) -> Category | H1: =TRIM('Raw Data'!H1) -> Quantity | I1: =TRIM('Raw Data'!I1) -> Unit Price (₦) | J1: =TRIM('Raw Data'!J1) -> Region | ... M1: =TRIM('Raw Data'!M1) -> Payment Status | N1: Year | O1: Month | P1: Day
A2: =PROPER(TRIM('Raw Data'!A2)) -> Txn001 | B2: 46235 | C2: =TRIM('Raw Data'!C2) -> C008 | D2: =PROPER(TRIM('Raw Data'!D2)) -> Joseph Adebayo | E2: =TRIM('Raw Data'!E2) -> P004 | F2: =PROPER(TRIM('Raw Data'!F2)) -> Sliced Bread | G2: =PROPER(TRIM('Raw Data'!G2)) -> Bakery | H2: =TRIM('Raw Data'!H2) -> 2 | I2: =VALUE('Raw Data'!I2) -> 2200 | J2: =PROPER(TRIM('Raw Data'!J2)) -> Lagos | K2: =PROPER(TRIM('Raw Data'!K2)) -> Chinedu | L2: =UPPER(TRIM('Raw Data'!L2)) -> CARD | M2: =PROPER(TRIM('Raw Data'!M2)) -> Paid | N2: =YEAR(B2) -> 2026
A3: =PROPER(TRIM('Raw Data'!A3)) -> Txn002 | B3: 46236 | C3: =TRIM('Raw Data'!C3) -> C005 | D3: =PROPER(TRIM('Raw Data'!D3)) -> Esther Johnson | E3: =TRIM('Raw Data'!E3) -> P007 | F3: =PROPER(TRIM('Raw Data'!F3)) -> Bottled Water | G3: =PROPER(TRIM('Raw Data'!G3)) -> Beverages | H3: =TRIM('Raw Data'!H3) -> 3 | I3: =VALUE('Raw Data'!I3) -> 500 | J3: =PROPER(TRIM('Raw Data'!J3)) -> Lagos | K3: =PROPER(TRIM('Raw Data'!K3)) -> Kemi | L3: =UPPER(TRIM('Raw Data'!L3)) -> TRANSFER | M3: =PROPER(TRIM('Raw Data'!M3)) -> Paid
A4: =PROPER(TRIM('Raw Data'!A4)) -> Txn003 | B4: 46237 | C4: =TRIM('Raw Data'!C4) -> C002 | D4: =PROPER(TRIM('Raw Data'!D4)) -> Daniel Okafor | E4: =TRIM('Raw Data'!E4) -> P002 | F4: =PROPER(TRIM('Raw Data'!F4)) -> Spaghetti | G4: =PROPER(TRIM('Raw Data'!G4)) -> Groceries | H4: =TRIM('Raw Data'!H4) -> 4 | I4: =VALUE('Raw Data'!I4) -> 1800 | J4: =PROPER(TRIM('Raw Data'!J4)) -> Ibadan | K4: =PROPER(TRIM('Raw Data'!K4)) -> Tolu | L4: =UPPER(TRIM('Raw Data'!L4)) -> POS | M4: =PROPER(TRIM('Raw Data'!M4)) -> Paid
A5: =PROPER(TRIM('Raw Data'!A5)) -> Txn004 | B5: 46238 | C5: =TRIM('Raw Data'!C5) -> C009 | D5: =PROPER(TRIM('Raw Data'!D5)) -> Deborah Obi | E5: =TRIM('Raw Data'!E5) -> P005 | F5: =PROPER(TRIM('Raw Data'!F5)) -> Meat Pie | G5: =PROPER(TRIM('Raw Data'!G5)) -> Bakery | H5: =TRIM('Raw Data'!H5) -> 5 | I5: =VALUE('Raw Data'!I5) -> 1800 | J5: =PROPER(TRIM('Raw Data'!J5)) -> Enugu | K5: =PROPER(TRIM('Raw Data'!K5)) -> Amaka | L5: =UPPER(TRIM('Raw Data'!L5)) -> CASH | M5: =PROPER(TRIM('Raw Data'!M5)) -> Paid
A6: =PROPER(TRIM('Raw Data'!A6)) -> Txn005 | B6: 46239 | C6: =TRIM('Raw Data'!C6) -> C006 | D6: =PROPER(TRIM('Raw Data'!D6)) -> David Yusuf | E6: =TRIM('Raw Data'!E6) -> P008 | F6: =PROPER(TRIM('Raw Data'!F6)) -> Liquid Soap | G6: =PROPER(TRIM('Raw Data'!G6)) -> Household | H6: =TRIM('Raw Data'!H6) -> 6 | I6: =VALUE('Raw Data'!I6) -> 3500 | J6: =PROPER(TRIM('Raw Data'!J6)) -> Abuja | K6: =PROPER(TRIM('Raw Data'!K6)) -> Chinedu | L6: =UPPER(TRIM('Raw Data'!L6)) -> CARD | M6: =PROPER(TRIM('Raw Data'!M6)) -> Pending
A7: =PROPER(TRIM('Raw Data'!A7)) -> Txn006 | B7: 46240 | C7: =TRIM('Raw Data'!C7) -> C003 | D7: =PROPER(TRIM('Raw Data'!D7)) -> Grace Adeyemi | E7: =TRIM('Raw Data'!E7) -> P003 | F7: =PROPER(TRIM('Raw Data'!F7)) -> Peak Milk | G7: =PROPER(TRIM('Raw Data'!G7)) -> Groceries | H7: =TRIM('Raw Data'!H7) -> 7 | I7: =VALUE('Raw Data'!I7) -> 3200 | J7: =PROPER(TRIM('Raw Data'!J7)) -> Abuja | K7: =PROPER(TRIM('Raw Data'!K7)) -> Kemi | L7: =UPPER(TRIM('Raw Data'!L7)) -> TRANSFER | M7: =PROPER(TRIM('Raw Data'!M7)) -> Paid
A8: =PROPER(TRIM('Raw Data'!A8)) -> Txn007 | B8: 46241 | C8: =TRIM('Raw Data'!C8) -> C010 | D8: =PROPER(TRIM('Raw Data'!D8)) -> Peter James | E8: =TRIM('Raw Data'!E8) -> P006 | F8: =PROPER(TRIM('Raw Data'!F8)) -> Malt Drink | G8: =PROPER(TRIM('Raw Data'!G8)) -> Beverages | H8: =TRIM('Raw Data'!H8) -> 8 | I8: =VALUE('Raw Data'!I8) -> 1200 | J8: =PROPER(TRIM('Raw Data'!J8)) -> Abuja | K8: =PROPER(TRIM('Raw Data'!K8)) -> Tolu | L8: =UPPER(TRIM('Raw Data'!L8)) -> POS | M8: =PROPER(TRIM('Raw Data'!M8)) -> Paid
A9: =PROPER(TRIM('Raw Data'!A9)) -> Txn008 | B9: 46242 | C9: =TRIM('Raw Data'!C9) -> C007 | D9: =PROPER(TRIM('Raw Data'!D9)) -> Miriam Balogun | E9: =TRIM('Raw Data'!E9) -> P001 | F9: =PROPER(TRIM('Raw Data'!F9)) -> Premium Rice 5Kg | G9: =PROPER(TRIM('Raw Data'!G9)) -> Groceries | H9: =TRIM('Raw Data'!H9) -> 1 | I9: =VALUE('Raw Data'!I9) -> 14500 | J9: =PROPER(TRIM('Raw Data'!J9)) -> Ibadan | K9: =PROPER(TRIM('Raw Data'!K9)) -> Amaka | L9: =UPPER(TRIM('Raw Data'!L9)) -> CASH | M9: =PROPER(TRIM('Raw Data'!M9)) -> Paid
A10: =PROPER(TRIM('Raw Data'!A10)) -> Txn009 | B10: 46243 | C10: =TRIM('Raw Data'!C10) -> C004 | D10: =PROPER(TRIM('Raw Data'!D10)) -> Samuel Eze | E10: =TRIM('Raw Data'!E10) -> P004 | F10: =PROPER(TRIM('Raw Data'!F10)) -> Sliced Bread | G10: =PROPER(TRIM('Raw Data'!G10)) -> Bakery | H10: =TRIM('Raw Data'!H10) -> 2 | I10: =VALUE('Raw Data'!I10) -> 2200 | J10: =PROPER(TRIM('Raw Data'!J10)) -> Enugu | K10: =PROPER(TRIM('Raw Data'!K10)) -> Chinedu | L10: =UPPER(TRIM('Raw Data'!L10)) -> CARD | M10: =PROPER(TRIM('Raw Data'!M10)) -> Paid
A11: =PROPER(TRIM('Raw Data'!A11)) -> Txn010 | B11: 46244 | C11: =TRIM('Raw Data'!C11) -> C001 | D11: =PROPER(TRIM('Raw Data'!D11)) -> Aisha Bello | E11: =TRIM('Raw Data'!E11) -> P007 | F11: =PROPER(TRIM('Raw Data'!F11)) -> Bottled Water | G11: =PROPER(TRIM('Raw Data'!G11)) -> Beverages | H11: =TRIM('Raw Data'!H11) -> 3 | I11: =VALUE('Raw Data'!I11) -> 500 | J11: =PROPER(TRIM('Raw Data'!J11)) -> Lagos | K11: =PROPER(TRIM('Raw Data'!K11)) -> Kemi | L11: =UPPER(TRIM('Raw Data'!L11)) -> TRANSFER | M11: =PROPER(TRIM('Raw Data'!M11)) -> Pending
A12: =PROPER(TRIM('Raw Data'!A12)) -> Txn011 | B12: 46245 | C12: =TRIM('Raw Data'!C12) -> C008 | D12: =PROPER(TRIM('Raw Data'!D12)) -> Joseph Adebayo | E12: =TRIM('Raw Data'!E12) -> P002 | F12: =PROPER(TRIM('Raw Data'!F12)) -> Spaghetti | G12: =PROPER(TRIM('Raw Data'!G12)) -> Groceries | H12: =TRIM('Raw Data'!H12) -> 4 | I12: =VALUE('Raw Data'!I12) -> 1800 | J12: =PROPER(TRIM('Raw Data'!J12)) -> Lagos | K12: =PROPER(TRIM('Raw Data'!K12)) -> Tolu | L12: =UPPER(TRIM('Raw Data'!L12)) -> POS | M12: =PROPER(TRIM('Raw Data'!M12)) -> Paid
A13: =PROPER(TRIM('Raw Data'!A13)) -> Txn012 | B13: 46246 | C13: =TRIM('Raw Data'!C13) -> C005 | D13: =PROPER(TRIM('Raw Data'!D13)) -> Aisha Bello | E13: =TRIM('Raw Data'!E13) -> P005 | F13: =PROPER(TRIM('Raw Data'!F13)) -> Meat Pie | G13: =PROPER(TRIM('Raw Data'!G13)) -> Bakery | H13: =TRIM('Raw Data'!H13) -> 5 | I13: =VALUE('Raw Data'!I13) -> 1800 | J13: =PROPER(TRIM('Raw Data'!J13)) -> Lagos | K13: =PROPER(TRIM('Raw Data'!K13)) -> Amaka | L13: =UPPER(TRIM('Raw Data'!L13)) -> CASH | M13: =PROPER(TRIM('Raw Data'!M13)) -> Paid
A14: =PROPER(TRIM('Raw Data'!A14)) -> Txn013 | B14: 46247 | C14: =TRIM('Raw Data'!C14) -> C002 | D14: =PROPER(TRIM('Raw Data'!D14)) -> Daniel Okafor | E14: =TRIM('Raw Data'!E14) -> P008 | F14: =PROPER(TRIM('Raw Data'!F14)) -> Liquid Soap | G14: =PROPER(TRIM('Raw Data'!G14)) -> Household | H14: =TRIM('Raw Data'!H14) -> 6 | I14: =VALUE('Raw Data'!I14) -> 3500 | J14: =PROPER(TRIM('Raw Data'!J14)) -> Ibadan | K14: =PROPER(TRIM('Raw Data'!K14)) -> Chinedu | L14: =UPPER(TRIM('Raw Data'!L14)) -> CARD | M14: =PROPER(TRIM('Raw Data'!M14)) -> Paid
... A101: =PROPER(TRIM('Raw Data'!A101)) -> Txn100 | B101: 46250 | C101: =TRIM('Raw Data'!C101) -> C001 | D101: =PROPER(TRIM('Raw Data'!D101)) -> Aisha Bello | E101: =TRIM('Raw Data'!E101) -> P005 | F101: =PROPER(TRIM('Raw Data'!F101)) -> Meat Pie | G101: =PROPER(TRIM('Raw Data'!G101)) -> Bakery | H101: =TRIM('Raw Data'!H101) -> 5 | I101: =VALUE('Raw Data'!I101) -> 1800 | J101: =PROPER(TRIM('Raw Data'!J101)) -> Lagos | K101: =PROPER(TRIM('Raw Data'!K101)) -> Amaka | L101: =UPPER(TRIM('Raw Data'!L101)) -> CASH | M101: =PROPER(TRIM('Raw Data'!M101)) -> Pending
A102: =PROPER(TRIM('Raw Data'!A102)) | E102: =TRIM('Raw Data'!E102) | F102: =PROPER(TRIM('Raw Data'!F102)) | J102: =PROPER(TRIM('Raw Data'!J102)) | L102: =UPPER(TRIM('Raw Data'!L102))
A103: =PROPER(TRIM('Raw Data'!A103)) | F103: =PROPER(TRIM('Raw Data'!F103)) | J103: =PROPER(TRIM('Raw Data'!J103)) | L103: =UPPER(TRIM('Raw Data'!L103))
A104: =PROPER(TRIM('Raw Data'!A104)) | F104: =PROPER(TRIM('Raw Data'!F104)) | J104: =PROPER(TRIM('Raw Data'!J104)) | L104: =UPPER(TRIM('Raw Data'!L104))
A105: =PROPER(TRIM('Raw Data'!A105)) | F105: =PROPER(TRIM('Raw Data'!F105)) | J105: =PROPER(TRIM('Raw Data'!J105)) | L105: =UPPER(TRIM('Raw Data'!L105))
A106: =PROPER(TRIM('Raw Data'!A106)) | F106: =PROPER(TRIM('Raw Data'!F106)) | J106: =PROPER(TRIM('Raw Data'!J106)) | L106: =UPPER(TRIM('Raw Data'!L106))
A107: =PROPER(TRIM('Raw Data'!A107)) | F107: =PROPER(TRIM('Raw Data'!F107)) | J107: =PROPER(TRIM('Raw Data'!J107)) | L107: =UPPER(TRIM('Raw Data'!L107))
A108: =PROPER(TRIM('Raw Data'!A108)) | F108: =PROPER(TRIM('Raw Data'!F108)) | J108: =PROPER(TRIM('Raw Data'!J108)) | L108: =UPPER(TRIM('Raw Data'!L108))
A109: =PROPER(TRIM('Raw Data'!A109)) | F109: =PROPER(TRIM('Raw Data'!F109)) | J109: =PROPER(TRIM('Raw Data'!J109)) | L109: =UPPER(TRIM('Raw Data'!L109))
A110: =PROPER(TRIM('Raw Data'!A110)) | F110: =PROPER(TRIM('Raw Data'!F110)) | J110: =PROPER(TRIM('Raw Data'!J110)) | L110: =UPPER(TRIM('Raw Data'!L110))
A111: =PROPER(TRIM('Raw Data'!A111)) | F111: =PROPER(TRIM('Raw Data'!F111)) | J111: =PROPER(TRIM('Raw Data'!J111)) | L111: =UPPER(TRIM('Raw Data'!L111))
A112: =PROPER(TRIM('Raw Data'!A112)) | F112: =PROPER(TRIM('Raw Data'!F112)) | J112: =PROPER(TRIM('Raw Data'!J112)) | L112: =UPPER(TRIM('Raw Data'!L112))
A113: =PROPER(TRIM('Raw Data'!A113)) | F113: =PROPER(TRIM('Raw Data'!F113)) | J113: =PROPER(TRIM('Raw Data'!J113)) | L113: =UPPER(TRIM('Raw Data'!L113))
A114: =PROPER(TRIM('Raw Data'!A114)) | F114: =PROPER(TRIM('Raw Data'!F114)) | J114: =PROPER(TRIM('Raw Data'!J114)) | L114: =UPPER(TRIM('Raw Data'!L114))
... A117: =PROPER(TRIM('Raw Data'!A117)) | F117: =PROPER(TRIM('Raw Data'!F117)) | J117: =PROPER(TRIM('Raw Data'!J117)) | L117: =UPPER(TRIM('Raw Data'!L117))
A118: =PROPER(TRIM('Raw Data'!A118)) | J118: =PROPER(TRIM('Raw Data'!J118)) | L118: =UPPER(TRIM('Raw Data'!L118))
A119: =PROPER(TRIM('Raw Data'!A119)) | J119: =PROPER(TRIM('Raw Data'!J119)) | L119: =UPPER(TRIM('Raw Data'!L119))
A120: =PROPER(TRIM('Raw Data'!A120)) | J120: =PROPER(TRIM('Raw Data'!J120)) | L120: =UPPER(TRIM('Raw Data'!L120))
A121: =PROPER(TRIM('Raw Data'!A121)) | J121: =PROPER(TRIM('Raw Data'!J121)) | L121: =UPPER(TRIM('Raw Data'!L121))
A122: =PROPER(TRIM('Raw Data'!A122)) | L122: =UPPER(TRIM('Raw Data'!L122))
A123: =PROPER(TRIM('Raw Data'!A123)) | L123: =UPPER(TRIM('Raw Data'!L123))
A124: =PROPER(TRIM('Raw Data'!A124)) | L124: =UPPER(TRIM('Raw Data'!L124))
A125: =PROPER(TRIM('Raw Data'!A125)) | L125: =UPPER(TRIM('Raw Data'!L125))
A126: =PROPER(TRIM('Raw Data'!A126)) | L126: =UPPER(TRIM('Raw Data'!L126))
A127: =PROPER(TRIM('Raw Data'!A127)) | L127: =UPPER(TRIM('Raw Data'!L127))
A128: =PROPER(TRIM('Raw Data'!A128)) | L128: =UPPER(TRIM('Raw Data'!L128))
...

Sheet Instructor Note
A1: Instructor Note
A2: This dataset contains intentional data-quality problems for students to discover.
A3: Problems include a duplicate, extra spaces, inconsistent capitalization, inconsistent payment status, and missing values.
A4: Students should not invent missing information.
